Workbook

Sheet Study Info
A1: General information | B1: LifeIP Meadow birds habitat
A2: Project:
A3: Place: | B3: Southwest Friesland
A4: Land use | B4: Protected sites, herb-rich meadows and ryegrass fields
A5: Person responsible for samples: | B5: Barbara Prack McCormick
A6: Contact: | B6: b.p.prack.mccormick@rug.nl
A8: Sampling date: | B8: August - November 2023
A9: Sampling storage: | B9: air dried/room temperature
A10: Analysis date: | B10: feb-march 2026
A11: Person performing the analysis: | B11: Msc Student Luciano Rivas
A12: Supervisor: | B12: Barbara Prack McCormick
A13: Data base link | B13: https://docs.google.com/spreadsheets/d/1Pc59ZJTg8LHCrCSjGJh5OfJrLX7u69Er_kCkicbP7mY/edit?gid=0#gid=0

Sheet Protocol
A1: Sample protocol | B1: Description
A2: Enzymes | B2: Laboratory analysis of samples previuosly kept in cold at 4°C. Two protocols were used: One for Urease (Cordero et al. (2019)) and another for acid phosphatase, arylsulfatase, and β-glucosidase (Tabatabai (1994))
A3: Birds | B3: Observer quantification (?)
A4: Bulk Density | B4: ?
A5: Organic matter | B5: Samples were collected at 0-10 cm depth with a soil sampler. Estimations of Soil Organic Matter (SOM), Particulate Organic Matter (POM), and Mineralized Associated Organic Matter (MAOM) were performed. SOM was analyzed with a incineration approach. POM was also estimated through this way, but with a previous filtering of the coarse fraction. MAOM was obtained as the weigth difference in the POM process.
A6: Coarse fraction | B6: The sand content was assessed by subtracting the POM fraction of the sample. Clay and silt content was obtained by subtracting MAOM
A7: Management | B7: Type of land management in our study site. Owners, grassland type, collective/organization in charge, and land use applied

Sheet Tables Source
A1: Table_ID | B1: explanation | C1: read_csv_link
A2: StudyInfo | B2: information about this data base | C2: https://docs.google.com/spreadsheets/d/1Pc59ZJTg8LHCrCSjGJh5OfJrLX7u69Er_kCkicbP7mY/edit?gid=0#gid=0
A3: Protocol | B3: Methodology explanation | C3: https://docs.google.com/spreadsheets/d/1Pc59ZJTg8LHCrCSjGJh5OfJrLX7u69Er_kCkicbP7mY/edit?gid=563558566#gid=563558566
A4: Tables Source | B4: list of tables of the data base (this table) | C4: https://docs.google.com/spreadsheets/d/1Pc59ZJTg8LHCrCSjGJh5OfJrLX7u69Er_kCkicbP7mY/edit?gid=158925398#gid=158925398
A5: Variables | B5: explanation of variables
A6: Points | B6: spatial data of the study area | C6: https://docs.google.com/spreadsheets/d/1Pc59ZJTg8LHCrCSjGJh5OfJrLX7u69Er_kCkicbP7mY/edit?gid=1600072753#gid=1600072753
A7: Soil type | B7: Soil composition and grassland characteristic | C7: https://docs.google.com/spreadsheets/d/1Pc59ZJTg8LHCrCSjGJh5OfJrLX7u69Er_kCkicbP7mY/edit?gid=321392057#gid=321392057
A8: Management | B8: Who manages the land | C8: https://docs.google.com/spreadsheets/d/1Pc59ZJTg8LHCrCSjGJh5OfJrLX7u69Er_kCkicbP7mY/edit?gid=341591005#gid=341591005
A9: Land Use | B9: Meadow management | C9: https://docs.google.com/spreadsheets/d/1Pc59ZJTg8LHCrCSjGJh5OfJrLX7u69Er_kCkicbP7mY/edit?gid=268592532#gid=268592532
A10: FactEnzymes 0-10cm | B10: Enzymes analysed | C10: https://docs.google.com/spreadsheets/d/1Pc59ZJTg8LHCrCSjGJh5OfJrLX7u69Er_kCkicbP7mY/edit?gid=1233139346#gid=1233139346
A11: FactBD 0-30cm | B11: Bulk density analysis | C11: https://docs.google.com/spreadsheets/d/1Pc59ZJTg8LHCrCSjGJh5OfJrLX7u69Er_kCkicbP7mY/edit?gid=1103075516#gid=1103075516
A12: Soil Moisture (summer) | B12: Soil moisture | C12: https://docs.google.com/spreadsheets/d/1Pc59ZJTg8LHCrCSjGJh5OfJrLX7u69Er_kCkicbP7mY/edit?gid=2025662198#gid=2025662198
A13: FactGodwits | B13: Godwits analysis | C13: https://docs.google.com/spreadsheets/d/1Pc59ZJTg8LHCrCSjGJh5OfJrLX7u69Er_kCkicbP7mY/edit?gid=914427057#gid=914427057
A14: SOM | B14: Soil organic matter analysis | C14: https://docs.google.com/spreadsheets/d/1Pc59ZJTg8LHCrCSjGJh5OfJrLX7u69Er_kCkicbP7mY/edit?gid=250711603#gid=250711603
A15: POM | B15: Particulate organic matter analysis | C15: https://docs.google.com/spreadsheets/d/1Pc59ZJTg8LHCrCSjGJh5OfJrLX7u69Er_kCkicbP7mY/edit?gid=1946457497#gid=1946457497
A16: MAOM | B16: Mineralized associated organic matter analysis | C16: https://docs.google.com/spreadsheets/d/1Pc59ZJTg8LHCrCSjGJh5OfJrLX7u69Er_kCkicbP7mY/edit?gid=735710415#gid=735710415

Sheet Variables
A1: Variables_ID | B1: Table_ID | C1: explanation
A2: Plot | B2: All | C2: Sampling plots
A3: Latitude | B3: Points | C3: Geographic coordinate (decimal degrees)
A4: Longitude | C4: Geographic coordinate (decimal degrees)
A5: Size (ha) | C5: Size of plots in hectares
A6: GoogleMapsLink | C6: Precise plot coordinate
A7: SamplingDate1 | C7: Samples 0-10 for enzymatic activity, pH and SOM10, POM10, MAOM10
A8: SamplingDate2 | C8: Soil samples 0-30 for carbon sequestration, bulk density, POM30, MAOM30
A9: Type | B9: Soil Type | C9: Grassland management
A10: Soil_mestwet | C10: Generalized classification of soil nutrients content for management purposes
A11: SoilType | C11: Physical composition of soil
A12: Owner | B12: Management | C12: Who owns the plot
A13: Collective | C13: Collective responsible for organizing
A14: Natura2000 | C14: Presence of Natuta2000 area = 1, No = 0
A15: MeadowID | B15: Land Use | C15: ID of studied meadow
A16: meadowtype | C16: Type of grassland in the meadow
A17: Management practice | C17: type of management practice at plot level
A18: Management type | C18: Clasification of management practice in Extensive or Intensive
A19: aryl_sul (ug/g dry soil/hour) | B19: FactEnzymes 0-10 cm | C19: Arylsulphatase (sulfur cycling) activity. Expressed as micrograms of product released per gram of dry soil per hour
A20: ac_fos (ug/g dry soil/hour) | C20: Acid-Phosphatase (Phosphorus cycling). Expressed as micrograms of product released per gram of dry soil per hour
A21: beta_glu (ug/g dry soil/hour) | C21: Beta-glucosidase (carbon cycling). Expressed as micrograms of product released per gram of dry soil per hour
A22: Urease (μg NH4/g soil/hour) | C22: Urease (Urea hydrolisis). Expressed as micrograms of ammonium (NH₄⁺) released per gram of soil per hour
A23: pH | C23: pH
A24: BD | B24: FactBD 0-30cm | C24: Bulk density of soil. Expressed in g/m3, 3 depths. 2 replicates per field
A25: Last_tillage | B25: FactManagement | C25: 1: 0-2 years ago; 2 : 2-5 years ago; 3: 6-10 years ago; 4: 11-15 years ago; 5: 16+ years ago
A26: Artificial_Fert | C26: 0: No; 1: Yes
A27: Slurry | C27: 0: No; 1: Yes
A28: Solid_manure | C28: 0: No; 1: Yes
A29: Fertilizer | C29: 0 - Only manure; 1: Only Slurry; 2: Art-ferti + slurry
A30: Grazing | C30: 0 - no grazing; 1: Little grazing (1 or 2x per year); 2: grazed regularly. Depends on the density of livestock and the rate of grazing on the field
A31: Mowing | C31: 0 - no mowing; 1: 1/2 times mowing; 2: 3/4 mowing; 3: 5+ times mowing; 9: mowed unsure how often
A32: Nature | C32: 0 - not owned by nature organisation; 1: owned by nature organization
A33: Water level | C33: 0: Water level at surface level; 3: Water level at mid surface level; 5: Water level at high depths
A34: Mean Moisture (%BD) | B34: Soil Moisture (summer) | C34: Moisture content as % of dry weight, dried at 105 degrees C. Samples collected in Autumn. Depth: 0-10, 10-20, 20-30. Only 2 replicates
A35: GodwitDensity | B35: FactGodwits | C35: Average number of godwits per hectare (2016-2022)
A36: Capsule_Tare | B36: SOM | C36: Weigth of capsule
A37: Soil_net_60 (g) | C37: Soil sample weigth
A38: Soil_Gross_105 (g) | C38: Soil sample + capsule weigth
A39: Soil_Net_105 (g) | C39: Soil sample weigth after treating it in the oven at 105°C for 24 hours
A40: Ashes_Gross (g) | C40: Soil sample after stove 550°C for 3 hours
...

Sheet Points
A1: Plot | B1: Lattitude | C1: Longitude | D1: Size(ha) | E1: GoogleMapsLink | F1: SamplingDate1 | G1: SamplingDate2
A2: 1 | B2: 53.014639 | C2: 5.4344167 | D2: 6 | E2: https://goo.gl/maps/4JGSVtjpVH8Wj1CU8 | F2: 15.08.23 | G2: 7.12.2023
A3: 2 | B3: 52.910389 | C3: 5.4289722 | D3: 3 | E3: https://goo.gl/maps/HoRjj9upF38WpkUXA | F3: 15.08.23 | G3: 29.11.2023
A4: 3 | B4: 52.927278 | C4: 5.4700833 | D4: 4 | E4: https://goo.gl/maps/u3JRNBe2NPadhALv8 | F4: 15.08.23 | G4: 29.11.2023
A5: 4 | B5: 52.89325 | C5: 5.3988056 | D5: 9 | E5: https://goo.gl/maps/nBmhfJsK7Sxrydzm8 | F5: 15.08.23 | G5: 29.11.2023
A6: 5 | B6: 52.978444 | C6: 5.4383611 | D6: 3 | E6: https://goo.gl/maps/fhoHpHkHpAr8M3hf7 | F6: 21.08.23 | G6: 24.11.2023
A7: 6 | B7: 53.008889 | C7: 5.4225278 | D7: 8 | E7: https://goo.gl/maps/hCBKyKATpvKHUAT18 | F7: 21.08.23 | G7: 30.11.2023
A8: 7 | B8: 53.006833 | C8: 5.4328333 | D8: 1 | E8: https://goo.gl/maps/7oGQrhte8j17Y5838 | F8: 21.08.23 | G8: 24.11.2023
A9: 8 | B9: 52.955056 | C9: 5.4195556 | D9: 2 | E9: https://goo.gl/maps/C7p2PECFtJtsMGsb8 | F9: 21.08.23 | G9: 23.11.2023
A10: 9 | B10: 52.9585 | C10: 5.41775 | D10: 15 | E10: https://goo.gl/maps/ghx3mGsvbxZmqWQX7 | F10: 21.08.23 | G10: 23.11.2023
A11: 10 | B11: 52.933667 | C11: 5.4445556 | D11: 4 | E11: https://goo.gl/maps/DZYapX2gdCHVvvbN7 | F11: 24.08.23 | G11: 30.11.2023
A12: 11 | B12: 52.937611 | C12: 5.4283611 | D12: 4 | E12: https://goo.gl/maps/FQs9N9UdxA1rZPky9 | F12: 24.08.23 | G12: 30.11.2023
A13: 12 | B13: 52.942417 | C13: 5.4281389 | D13: 5 | E13: https://goo.gl/maps/FzEKeGqgcvctREQr8 | F13: 24.08.23 | G13: 30.11.2023
... A35: 34 | B35: 52.92575 | C35: 5.4417778 | D35: 3 | E35: https://maps.app.goo.gl/ZoizHFxiKzAaAPYw5 | F35: 26.09.23 | G35: 23.11.2023

Sheet Soil type
A1: Plot | B1: Type | C1: Soil_mestwet | D1: SoilType
A2: 1 | B2: Permanent grassland | C2: Clay | D2: Light loam (70%) heavy loam (30%)
A3: 2 | B3: Permanent grassland | C3: Clay | D3: Heavy loam (100%)
A4: 3 | B4: Grassland, natural. Main function agriculture | C4: Clay | D4: Heavy clay (100%)
A5: 4 | B5: Permanent grassland | C5: Clay | D5: Light loam (52%) heavy loam (48%)
A6: 5 | B6: Temporary grassland | C6: Clay | D6: Light loam (19%) heavy loam (59%) built-up area etc. (22%)
A7: 6 | B7: Permanent grassland | C7: Clay | D7: Light loam (100%)
A8: 7 | B8: Permanent grassland | C8: Clay | D8: Light loam (100%)
A9: 8 | B9: Grassland, natural. Main function agriculture | C9: Clay | D9: Light loam (100%)
A10: 9 | B10: Grassland, natural. Main function agriculture | C10: Clay | D10: Light loam (100%)
A11: 10 | B11: Permanent grassland | C11: Clay | D11: Heavy clay (100%)
A12: 11 | B12: Permanent grassland | C12: Clay | D12: Heavy loam (21%) light clay (79%)
A13: 12 | B13: Permanent grassland | C13: Clay | D13: Light loam (31%) heavy loam (69%)
... A35: 34 | B35: Grassland, natural. Main function agriculture | C35: Sand | D35: Light loam (100%)

Sheet Ownership
A1: Plot | B1: Owner | C1: Contact Person | D1: phone/email | E1: Collective | F1: Natura2000
A2: 1 | B2: Epke and Anke Zonderland | C2: Epke and Anke Zonderland | D2: ehzonderlandbedrijf@outlook.com | E2: Cooperatieve Vereniging Sudwestkust U.A. | F2: 0
A3: 2 | B3: Niek en Annie Galama | C3: Niek en Annie Galama | D3: niekenannie@hetnet.nl | E3: Cooperatieve Vereniging Sudwestkust U.A. | F3: 0
A4: 3 | B4: Staatsbosbeheer | C4: Sietze Henk Haijtema | D4: +31 6 36381547 | E4: Cooperatieve Vereniging Sudwestkust U.A. | F4: 1
A5: 4 | B5: Niek en Annie Galama | C5: Niek en Annie Galama | D5: niekenannie@hetnet.nl | F5: 0
A6: 5 | B6: Jakob van der Valk (field station farm) | C6: Jakob van der Valk (field station farm) | D6: +31 6 13677463 | F6: 0
A7: 6 | B7: Pieter van der Valk | C7: Pieter van der Valk | D7: 06 1356 1835 | E7: Cooperatieve Vereniging Sudwestkust U.A. | F7: 0
A8: 7 | B8: Pieter van der Valk | C8: Pieter van der Valk | D8: 06 1356 1835 | E8: Cooperatieve Vereniging Sudwestkust U.A. | F8: 0
A9: 8 | B9: Staatsbosbeheer | C9: Durk Venema | D9: 0612723823/ D.Venema@staatsbosbeheer.nl | E9: Cooperatieve Vereniging Sudwestkust U.A. | F9: 1
A10: 9 | B10: Staatsbosbeheer | C10: Durk Venema | D10: 0612723823/ D.Venema@staatsbosbeheer.nl | E10: Cooperatieve Vereniging Sudwestkust U.A. | F10: 1
A11: 10 | B11: Atze Bosch | C11: Atze Bosch | D11: +31 6 34038967 | E11: Cooperatieve Vereniging Sudwestkust U.A. | F11: 0
A12: 11 | B12: Jeroen Van Middelaar | C12: Jeroen Van Middelaar | D12: +31 6 25127725 | E12: Cooperatieve Vereniging Sudwestkust U.A. | F12: 0
A13: 12 | B13: Jeroen Van Middelaar | C13: Jeroen Van Middelaar | D13: +31 6 25127725 | E13: Cooperatieve Vereniging Sudwestkust U.A. | F13: 0
A14: 13 | B14: Chris Zonderland | C14: Chris Zonderland | D14: +31 6 45332267 | E14: Cooperatieve Vereniging Sudwestkust U.A. | F14: 0
A15: 14 | B15: Bote de Boer | C15: Bote de Boer | D15: +31 6 81935300 | E15: Cooperatieve Vereniging Sudwestkust U.A. | F15: 0
A16: 15 | B16: Bote de Boer | C16: Bote de Boer | D16: +31 6 81935300 | E16: Cooperatieve Vereniging Sudwestkust U.A. | F16: 0
A17: 16 | B17: Bote de Boer | C17: Bote de Boer | D17: +31 6 81935300 | E17: Cooperatieve Vereniging Sudwestkust U.A. | F17: 0
A18: 17 | B18: Sietse Hibma | C18: Sietse Hibma | D18: +31 517532107 | E18: Cooperatieve Vereniging Sudwestkust U.A. | F18: 0
... A33: 32 | B33: Hielkje Van der Wal | C33: Hielkje Van der Wal | D33: +31 6 22836180 | E33: Cooperatieve Vereniging Sudwestkust U.A. | F33: 0
A34: 33 | B34: Hielkje Van der Wal | C34: Hielkje Van der Wal | D34: +31 6 22836180 | F34: 0
A35: 34 | B35: Staatsbosbeheer | C35: Durk Venema | D35: 0612723823/ D.Venema@staatsbosbeheer.nl | E35: Cooperatieve Vereniging Sudwestkust U.A. | F35: 0

Sheet Farms categorization
A1: Plot | B1: Owner | C1: meadowtype | D1: ManagedYesNo | E1: Management type | F1: AES
A2: 1 | B2: Epke and Anke Zonderland | C2: HerbRich | D2: AES | E2: Intermediate | F2: DelayedMowing | H2: Diversified | I2: ProtectedSite + HerbRich fields
A3: 2 | B3: Niek en Annie Galama | C3: RyeGrass | D3: Conventional Meadows | E3: Intensive | F3: IntensiveAgriculture | H3: Intermediate | I3: RyeGrass fields with AES/conservation intervention
A4: 3 | B4: Staatsbosbeheer | C4: ProtectedSite | D4: Site Protection | E4: Diversified | F4: SiteProtection | H4: Intensive | I4: RyeGrass + Conventional Meadows / IntensiveAgriculture
A5: 4 | B5: Niek en Annie Galama | C5: RyeGrass | D5: Conventional Meadows | E5: Intensive | F5: IntensiveAgriculture
A6: 5 | B6: Jakob van der Valk (field station farm) | C6: RyeGrass | D6: Conventional Meadows | E6: Intensive | F6: IntensiveAgriculture | H6: ProtectedSite | I6: Diversified / Protected
A7: 6 | B7: Pieter van der Valk | C7: RyeGrass | D7: AES | E7: Intermediate | F7: NestProtection | H7: HerbRich | I7: Diversified
A8: 7 | B8: Pieter van der Valk | C8: HerbRich | D8: Conventional Meadows | E8: Intensive | F8: IntensiveAgriculture | H8: RyeGrass + AES | I8: Intermediate
A9: 8 | B9: Staatsbosbeheer | C9: ProtectedSite | D9: Site Protection | E9: Diversified | F9: SiteProtection | H9: RyeGrass + Conventional Meadows | I9: Intensive
A10: 9 | B10: Staatsbosbeheer | C10: ProtectedSite | D10: Site Protection | E10: Diversified | F10: SiteProtection
A11: 10 | B11: Atze Bosch | C11: HerbRich | D11: AES | E11: Diversified | F11: HerbRich
A12: 11 | B12: Jeroen Van Middelaar | C12: HerbRich | D12: Site Protection | E12: Diversified | F12: SiteProtection
A13: 12 | B13: Jeroen Van Middelaar | C13: RyeGrass | D13: Site Protection | E13: Intermediate | F13: SiteProtection
A14: 13 | B14: Chris Zonderland | C14: RyeGrass | D14: AES | E14: Intermediate | F14: NestProtection
A15: 14 | B15: Bote de Boer | C15: HerbRich | D15: AES | E15: Diversified | F15: HerbRich
A16: 15 | B16: Bote de Boer | C16: HerbRich | D16: AES | E16: Intermediate | F16: NestProtection
A17: 16 | B17: Bote de Boer | C17: RyeGrass | D17: AES | E17: Intermediate | F17: NestProtection
A18: 17 | B18: Sietse Hibma | C18: HerbRich | D18: AES | E18: Diversified | F18: HerbRich
A19: 18 | B19: Sietse Hibma | C19: HerbRich | D19: AES | E19: Intermediate | F19: NestProtection
A20: 19 | B20: It Fryske Gea | C20: ProtectedSite | D20: Site Protection | E20: Diversified | F20: SiteProtection
A21: 20 | B21: Neighbour from Durk B | C21: RyeGrass | D21: Conventional Meadows | E21: Intensive | F21: IntensiveAgriculture
... A35: 34 | B35: Staatsbosbeheer | C35: ProtectedSite | D35: Site Protection | E35: Diversified | F35: SiteProtection

Sheet Land Use
A1: Plot | B1: MeadowID | C1: meadowtype | D1: Management type
A2: 1 | B2: 16077 | C2: HerbRich | D2: Diversified
A3: 2 | B3: 130005 | C3: RyeGrass | D3: Intensive
A4: 3 | B4: 129014 | C4: ProtectedSite | D4: Diversified
A5: 4 | B5: 128006 | C5: RyeGrass | D5: Intensive
A6: 5 | B6: 114107 | C6: RyeGrass | D6: Intensive
A7: 6 | B7: 16082 | C7: RyeGrass | D7: Intensive
A8: 7 | B8: 16104 | C8: HerbRich | D8: Diversified
A9: 8 | B9: 25015 | C9: ProtectedSite | D9: Diversified
A10: 9 | B10: 25006 | C10: ProtectedSite | D10: Diversified
A11: 10 | B11: 98039 | C11: HerbRich | D11: Diversified
A12: 11 | B12: 98026 | C12: HerbRich | D12: Diversified
A13: 12 | B13: 98012 | C13: RyeGrass | D13: Intensive
A14: 13 | B14: 161001 | C14: RyeGrass | D14: Intensive
A15: 14 | C15: HerbRich | D15: Diversified
A16: 15 | C16: HerbRich | D16: Intensive
A17: 16 | C17: RyeGrass | D17: Intensive
A18: 17 | C18: HerbRich | D18: Diversified
A19: 18 | C19: HerbRich | D19: Diversified
A20: 19 | C20: ProtectedSite | D20: Diversified
A21: 20 | B21: 568003 | C21: RyeGrass | D21: Intensive
A22: 21 | B22: 568020 | C22: HerbRich | D22: Diversified
A23: 22 | B23: 568027 | C23: HerbRich | D23: Diversified
A24: 23 | B24: 100028 | C24: ProtectedSite | D24: Diversified
A25: 24 | B25: 100021 | C25: ProtectedSite | D25: Diversified
A26: 25 | B26: 114029 | C26: ProtectedSite | D26: Diversified
A27: 26 | B27: 127008 | C27: ProtectedSite | D27: Diversified
A28: 27 | B28: 162028 | C28: HerbRich | D28: Diversified
A29: 28 | B29: 162027 | C29: RyeGrass | D29: Intensive
A30: 29 | B30: 129054 | C30: ProtectedSite | D30: Diversified
A31: 30 | B31: 129047 | C31: RyeGrass | D31: Intensive
A32: 31 | B32: 143005 | C32: ProtectedSite | D32: Diversified
... A35: 34 | B35: 69033 | C35: ProtectedSite | D35: Diversified

Sheet FactEnzymes 0-10cm
A1: Plot | B1: Replicate | C1: aryl_sul (ug/g dry soil/hour) | D1: ac_fos (ug/g dry soil/hour) | E1: beta_glu (ug/g dry soil/hour) | F1: Urease (μg NH4/g soil/hour) | G1: pH
A2: 1 | B2: 1 | C2: 894.7235 | D2: 1973.9355 | E2: 597.14286 | F2: 96.323207 | G2: 5.93
A3: 1 | B3: 2 | C3: 838.59445 | D3: 1574.7742 | E3: 509.61904 | F3: 101.38161 | G3: 6.03
A4: 1 | B4: 3 | C4: 897.23502 | D4: 1797.3548 | E4: 616.90476 | F4: 119.79436 | G4: 5.96
A5: 2 | B5: 1 | C5: 815.69126 | D5: 1965.5484 | E5: 507.47619 | F5: 161.24219 | G5: 5.7
A6: 2 | B6: 2 | C6: 862.67279 | D6: 1865.8065 | E6: 507.47619 | F6: 153.68437 | G6: 5.79
A7: 2 | B7: 3 | C7: 912.14286 | D7: 1980.5806 | E7: 550.14285 | F7: 167.54498 | G7: 5.67
A8: 3 | B8: 1 | C8: 793.50231 | D8: 1958.3225 | E8: 463.92857 | F8: 76.838365 | G8: 4.73
A9: 3 | B9: 2 | C9: 681.98158 | D9: 1541.4193 | E9: 423.28573 | F9: 86.170245 | G9: 4.58
A10: 3 | B10: 3 | C10: 666.03687 | D10: 1702.2581 | E10: 355.28571 | F10: 85.266197 | G10: 4.74
A11: 4 | B11: 1 | C11: 629.81568 | D11: 887.03226 | E11: 342.0238 | F11: 110.21786 | G11: 6.17
A12: 4 | B12: 2 | C12: 636.8894 | D12: 661.09678 | E12: 339.04762 | F12: 130.99601 | G12: 6.84
A13: 4 | B13: 3 | C13: 733.80183 | D13: 816.77421 | E13: 383.88096 | F13: 96.56783 | G13: 6.46
... A93: 31 | B93: 2 | C93: 356.42344 | D93: 1855.4761 | E93: 339.84663 | F93: 81.814581 | G93: 4.42
A94: 31 | B94: 3 | C94: 493.51265 | D94: 2147.7213 | E94: 296.64468 | F94: 74.551471 | G94: #
A95: 32 | B95: 1 | C95: 608.99701 | D95: 2150.7148 | E95: 406.81158 | F95: 163.0519 | G95: 5.56
A96: 32 | B96: 2 | C96: 566.10865 | D96: 2122.5007 | E96: 468.0154 | F96: 162.50329 | G96: 5.48
A97: 32 | B97: 3 | C97: 692.09375 | D97: 2402.2477 | E97: 516.63537 | F97: 168.697 | G97: 5.53
A98: 33 | B98: 1 | C98: 652.94348 | D98: 2123.1742 | E98: 529.34103 | F98: 123.58408 | G98: 5.76
A99: 33 | B99: 2 | C99: 521.27253 | D99: 1588.4516 | E99: 473.97865 | F99: 95.137463 | G99: 6.09
A100: 33 | B100: 3 | C100: 576.47445 | D100: 1554.9238 | E100: 360.5279 | F100: 107.96872 | G100: 5.86
A101: 34 | B101: 1 | C101: 524.81654 | D101: 1395.2929 | E101: 294.10391 | F101: 88.572327 | G101: 4.98
A102: 34 | B102: 2 | C102: 672.27231 | D102: 1344.7019 | E102: 298.93485 | F102: 91.09809 | G102: 4.94
A103: 34 | B103: 3 | C103: 659.11805 | D103: 1296.9548 | E103: 369.60478 | F103: 78.603103 | G103: 4.92

Sheet FactBD 0-30cm
A1: Plot | B1: Replicate | C1: core | D1: depth | E1: sampleID | F1: proces_date | G1: BD
A2: 1 | B2: 1 | C2: a | D2: 0-10 | E2: 1 | F2: 45308 | G2: 781.03559
A3: 1 | B3: 1 | C3: b | D3: 10-20 | E3: 2 | F3: 45308 | G3: 1003.3698
A4: 1 | B4: 1 | C4: c | D4: 20-30 | E4: 3 | F4: 45308 | G4: 1371.9254
A5: 1 | B5: 2 | C5: a | D5: 0-10 | E5: 4 | F5: 45308 | G5: 812.49058
A6: 1 | B6: 2 | C6: b | D6: 10-20 | E6: 5 | F6: 45308 | G6: 1086.6983
A7: 1 | B7: 2 | C7: c | D7: 20-30 | E7: 6 | F7: 45308 | G7: 1356.3685
A8: 2 | B8: 1 | C8: a | D8: 0-10 | E8: 7 | F8: 45308 | G8: 999.37825
A9: 2 | B9: 1 | C9: b | D9: 10-20 | E9: 8 | F9: 45308 | G9: 1115.2875
A10: 2 | B10: 1 | C10: c | D10: 20-30 | E10: 9 | F10: 45308 | G10: 1213.8999
A11: 2 | B11: 2 | C11: a | D11: 0-10 | E11: 10 | F11: 45308 | G11: 920.31433
A12: 2 | B12: 2 | C12: b | D12: 10-20 | E12: 11 | F12: 45308 | G12: 1243.7515
A13: 2 | B13: 2 | C13: c | D13: 20-30 | E13: 12 | F13: 45308 | G13: 1227.5634
... A181: 30 | B181: 2 | C181: c | D181: 20-30 | E181: 180 | F181: 45313 | G181: 1239.3334
A182: 31 | B182: 1 | C182: a | D182: 0-10 | E182: 181
A183: 31 | B183: 1 | C183: b | D183: 10-20 | E183: 182
A184: 31 | B184: 1 | C184: c | D184: 20-30 | E184: 183
A185: 31 | B185: 2 | C185: a | D185: 0-10 | E185: 184
A186: 31 | B186: 2 | C186: b | D186: 10-20 | E186: 185
A187: 31 | B187: 2 | C187: c | D187: 20-30 | E187: 186
A188: 32 | B188: 1 | C188: a | D188: 0-10 | E188: 187 | F188: 45313 | G188: 844.78141
A189: 32 | B189: 1 | C189: b | D189: 10-20 | E189: 188 | F189: 45313 | G189: 997.96244
A190: 32 | B190: 1 | C190: c | D190: 20-30 | E190: 189 | F190: 45313 | G190: 1054.5098
A191: 32 | B191: 2 | C191: a | D191: 0-10 | E191: 190 | F191: 45313 | G191: 927.9222
A192: 32 | B192: 2 | C192: b | D192: 10-20 | E192: 191 | F192: 45313 | G192: 1025.6988
A193: 32 | B193: 2 | C193: c | D193: 20-30 | E193: 192 | F193: 45313 | G193: 1238.8387
A194: 33 | B194: 1 | C194: a | D194: 0-10 | E194: 193 | F194: 45313 | G194: 796.91661
A195: 33 | B195: 1 | C195: b | D195: 10-20 | E195: 194 | F195: 45313 | G195: 1090.5193
A196: 33 | B196: 1 | C196: c | D196: 20-30 | E196: 195 | F196: 45313 | G196: 1094.6132
A197: 33 | B197: 2 | C197: a | D197: 0-10 | E197: 196 | F197: 45313 | G197: 937.15059
A198: 33 | B198: 2 | C198: b | D198: 10-20 | E198: 197 | F198: 45313 | G198: 1129.2068
A199: 33 | B199: 2 | C199: c | D199: 20-30 | E199: 198 | F199: 45313 | G199: 1066.7063
... A205: 34 | B205: 2 | C205: c | D205: 20-30 | E205: 204 | F205: 45308 | G205: 1422.076

Sheet FactManagement
A1: Plot | B1: Last_tillage | C1: Artificial_Fert | D1: Slurry | E1: Solid_manure | F1: Fertilizer | G1: Grazing | H1: Mowing | I1: Nature | J1: Waterlevel
A2: 1 | B2: 5 | C2: 0 | D2: 1 | E2: 1 | F2: 1 | G2: 2 | H2: 1 | I2: 0 | J2: 5
A3: 2 | C3: 1 | D3: 1 | E3: 0 | F3: 2 | G3: 1 | H3: 3 | I3: 0 | J3: 2
A4: 3 | B4: 5 | C4: 0 | D4: 0 | E4: 1 | F4: 0 | G4: 0 | H4: 1 | I4: 1 | J4: 2
A5: 4 | C5: 1 | D5: 1 | E5: 0 | F5: 2 | G5: 1 | H5: 3 | I5: 0 | J5: 5
A6: 5 | B6: 3 | C6: 1 | D6: 1 | E6: 0 | F6: 2 | G6: 2 | H6: 3 | I6: 0 | J6: 3
A7: 6 | B7: 3 | C7: 1 | D7: 1 | E7: 0 | F7: 2 | G7: 0 | H7: 2 | I7: 0 | J7: 5
A8: 7 | B8: 5 | C8: 0 | D8: 1 | E8: 1 | F8: 1 | G8: 0 | H8: 1 | I8: 0 | J8: 5
A9: 8 | B9: 5 | C9: 0 | D9: 0 | E9: 1 | F9: 0 | G9: 1 | H9: 1 | I9: 1 | J9: 3
A10: 9 | B10: 5 | C10: 0 | D10: 0 | E10: 1 | F10: 0 | G10: 1 | H10: 1 | I10: 1 | J10: 3
A11: 10 | B11: 5 | C11: 0 | D11: 0 | E11: 1 | F11: 0 | G11: 2 | H11: 1 | I11: 0 | J11: 2
A12: 11 | B12: 4 | C12: 0 | D12: 0 | E12: 1 | F12: 0 | G12: 1 | H12: 2 | I12: 0 | J12: 3
A13: 12 | B13: 5 | C13: 1 | D13: 1 | E13: 0 | F13: 2 | G13: 2 | H13: 1 | I13: 0 | J13: 3
A14: 13 | B14: 4 | C14: 1 | D14: 1 | E14: 0 | F14: 2 | G14: 0 | H14: 3 | I14: 0 | J14: 3
A15: 14 | B15: 5 | C15: 0 | D15: 0 | E15: 1 | F15: 0 | G15: 2 | H15: 1 | I15: 0 | J15: 3
A16: 15 | B16: 5 | C16: 0 | D16: 1 | E16: 0 | F16: 1 | G16: 2 | H16: 1 | I16: 0 | J16: 3
A17: 16 | B17: 4 | C17: 1 | D17: 1 | E17: 0 | F17: 2 | G17: 0 | H17: 3 | I17: 0 | J17: 3
... A35: 34 | B35: 5 | C35: 0 | D35: 0 | E35: 1 | F35: 0 | G35: 1 | H35: 1 | I35: 1 | J35: 3

Sheet Soil Moisture (summer)
A1: Plot | B1: Mean Moisture (%DS)
A2: 1 | B2: 63.57
A3: 2 | B3: 50.22
A4: 3 | B4: 63.17
A5: 4 | B5: 35.62
A6: 5 | B6: 39.98
A7: 6 | B7: 41.67
A8: 7 | B8: 48.88
A9: 8 | B9: 45.77
A10: 9 | B10: 57.61
A11: 10 | B11: 55.44
A12: 11 | B12: 49.35
A13: 12 | B13: 48.44
... A35: 34 | B35: 72.29

Sheet FactGodwits
A1: Plot | B1: GodwitDensity | C1: HA | D1: Area | E1: Peremiter | F1: X | G1: Y | H1: YEAR | I1: MeadowHa | J1: Territorials | K1: TerritorialsPerHa | L1: Column 16 | M1: ManagedYesNo | N1: IncomePerHa | O1: PackagesNumber | P1: group
A2: 1 | B2: 0.288 | C2: 6.3604159 | D2: 63604.159 | E2: 1174.9854 | F2: 5.4328818 | G2: 53.015632 | H2: 2023 | I2: 6.3604159 | J2: 4.5 | K2: 0.70750091 | M2: AES | N2: 781.54597 | O2: 3 | P2: DelayedMowing
A3: 2 | B3: 0 | C3: 3.2793904 | D3: 32793.904 | E3: 752.61247 | F3: 5.4303309 | G3: 52.910082 | H3: 2023 | I3: 3.2793904 | J3: 0 | K3: 0 | L3: Intermediate | M3: Conventional Meadows | P3: IntensiveAgriculture
A4: 3 | B4: 0.045 | C4: 3.67807 | D4: 36780.7 | E4: 825.73482 | F4: 5.4705693 | G4: 52.928294 | H4: 2023 | I4: 3.67807 | J4: 0 | K4: 0 | L4: Intensive | M4: Site Protection | P4: SiteProtection
A5: 4 | B5: 0 | C5: 2.0424452 | D5: 20424.452 | E5: 610.83983 | F5: 5.3990786 | G5: 52.892456 | H5: 2023 | I5: 2.0424452 | J5: 0 | K5: 0 | L5: Diversified | M5: Conventional Meadows | P5: IntensiveAgriculture
A6: 5 | B6: 0 | C6: 2.8442467 | D6: 28442.467 | E6: 763.43916 | F6: 5.4378963 | G6: 52.978498 | H6: 2023 | I6: 2.8442467 | J6: 0 | K6: 0 | L6: Intensive | M6: Conventional Meadows | P6: IntensiveAgriculture
A7: 6 | B7: 0.226 | C7: 11.446829 | D7: 114468.29 | E7: 1506.6203 | F7: 5.4222744 | G7: 53.008342 | H7: 2023 | I7: 11.446829 | J7: 3 | K7: 0.2620813 | M7: AES | N7: 94.995913 | O7: 3 | P7: NestProtection
A8: 7 | B8: 0 | C8: 1.3826236 | D8: 13826.236 | E8: 602.0866 | F8: 5.4329617 | G8: 53.006824 | H8: 2023 | I8: 1.3826236 | J8: 0 | K8: 0 | L8: Intensive | M8: Conventional Meadows | P8: IntensiveAgriculture
A9: 8 | B9: 0.792 | C9: 1.8935636 | D9: 18935.636 | E9: 614.54324 | F9: 5.4198269 | G9: 52.954906 | H9: 2023 | I9: 1.8935636 | J9: 2 | K9: 1.0562096 | M9: Site Protection | P9: SiteProtection
A10: 9 | B10: 0.964 | C10: 3.7158049 | D10: 37158.049 | E10: 771.19498 | F10: 5.4176556 | G10: 52.958559 | H10: 2023 | I10: 3.7158049 | J10: 5.5 | K10: 1.4801638 | M10: Site Protection | P10: SiteProtection
A11: 10 | B11: 0.812 | C11: 3.6928957 | D11: 36928.957 | E11: 808.26871 | F11: 5.4447614 | G11: 52.933515 | H11: 2023 | I11: 3.6928957 | J11: 1.5 | K11: 0.40618532 | M11: AES | N11: 1538.9629 | O11: 3 | P11: HerbRich
A12: 11 | B12: 0.323 | C12: 3.6167186 | D12: 36167.186 | E12: 761.13999 | F12: 5.428143 | G12: 52.937891 | H12: 2023 | I12: 3.6167186 | J12: 2 | K12: 0.55298745 | M12: Site Protection | P12: SiteProtection
A13: 12 | B13: 0.098 | C13: 11.046313 | D13: 110463.13 | E13: 1856.9945 | F13: 5.42903 | G13: 52.941984 | H13: 2023 | I13: 11.046313 | J13: 0 | K13: 0 | L13: Intermediate | M13: Site Protection | P13: SiteProtection
A14: 13 | B14: 0.095 | C14: 6.9853486 | D14: 69853.486 | E14: 1081.6974 | F14: 5.4425455 | G14: 52.929597 | H14: 2023 | I14: 6.9853486 | J14: 0 | K14: 0 | L14: Intensive | M14: AES | N14: 100.06636 | O14: 2 | P14: NestProtection
A15: 14 | C15: 0.566 | H15: 2023 | I15: 0.566 | J15: 0 | K15: 0 | L15: Diversified | M15: AES | N15: 1424.2329 | O15: 5 | P15: HerbRich
A16: 15 | C16: 2.122 | H16: 2023 | I16: 2.122 | J16: 0 | K16: 0 | L16: Diversified | M16: AES | N16: 762.1962 | O16: 5 | P16: NestProtection
A17: 16 | C17: 1.341 | H17: 2023 | I17: 1.341 | J17: 0 | K17: 0 | L17: Diversified | M17: AES | N17: 332.11584 | O17: 3 | P17: NestProtection
A18: 17 | C18: 8.801 | H18: 2023 | I18: 8.801 | J18: 0 | K18: 0 | L18: Diversified | M18: AES | N18: 1393.5818 | O18: 5 | P18: HerbRich
A19: 18 | C19: 0.864 | H19: 2023 | I19: 0.864 | J19: 0 | K19: 0 | L19: Intermediate | M19: AES | N19: 203.17319 | O19: 2 | P19: NestProtection
A20: 19 | C20: 6.479 | H20: 2023 | I20: 6.479 | J20: 0 | K20: 0 | L20: Intermediate | M20: Site Protection | P20: SiteProtection
A21: 20 | B21: 0.083 | C21: 2.0106696 | D21: 20106.696 | E21: 743.91922 | F21: 5.5183074 | G21: 52.988984 | H21: 2023 | I21: 2.0106696 | J21: 0 | K21: 0 | L21: Diversified | M21: Conventional Meadows | P21: IntensiveAgriculture
A22: 21 | B22: 1.547 | C22: 1.2931181 | D22: 12931.181 | E22: 718.23079 | F22: 5.5139904 | G22: 52.985656 | H22: 2023 | I22: 1.2931181 | J22: 3 | K22: 2.3199737 | M22: AES | N22: 1274.212 | O22: 5 | P22: HerbRich
A23: 22 | B23: 1.525 | C23: 3.9357143 | D23: 39357.143 | E23: 1049.2287 | F23: 5.5123048 | G23: 52.983447 | H23: 2023 | I23: 3.9357143 | J23: 5 | K23: 1.2704174 | M23: AES | N23: 1045.363 | O23: 3 | P23: HerbRich
A24: 23 | B24: 0.19 | C24: 3.5030803 | D24: 35030.803 | E24: 768.29932 | F24: 5.5003088 | G24: 52.997944 | H24: 2023 | I24: 3.5030803 | J24: 2 | K24: 0.5709261 | M24: Site Protection | P24: SiteProtection
A25: 24 | B25: 1.442 | C25: 3.2368821 | D25: 32368.821 | E25: 938.75412 | F25: 5.4964055 | G25: 52.996047 | H25: 2023 | I25: 3.2368821 | J25: 5.5 | K25: 1.699166 | M25: Site Protection | P25: SiteProtection
A26: 25 | B26: 0 | C26: 2.0617642 | D26: 20617.642 | E26: 655.9172 | F26: 5.457926 | G26: 53.001225 | H26: 2023 | I26: 2.0617642 | J26: 0 | K26: 0 | L26: Intermediate | M26: Site Protection | P26: SiteProtection
A27: 26 | B27: 0 | C27: 2.6445413 | D27: 26445.413 | E27: 782.89395 | F27: 5.41107 | G27: 52.911289 | H27: 2023 | I27: 2.6445413 | J27: 0 | K27: 0 | L27: Intermediate | M27: Site Protection | P27: SiteProtection
A28: 27 | B28: 0.348 | C28: 5.9785792 | D28: 59785.792 | E28: 1212.9086 | F28: 5.4441522 | G28: 52.899213 | H28: 2023 | I28: 5.9785792 | J28: 2 | K28: 0.33452764 | M28: AES | N28: 786.12244 | O28: 4 | P28: Mosaics
A29: 28 | B29: 0.23 | C29: 3.2556155 | D29: 32556.155 | E29: 879.96578 | F29: 5.4421015 | G29: 52.899127 | H29: 2023 | I29: 3.2556155 | J29: 0 | K29: 0 | L29: Diversified | M29: Conventional Meadows | P29: IntensiveAgriculture
A30: 29 | B30: 0.779 | C30: 2.4606473 | D30: 24606.473 | E30: 744.32599 | F30: 5.4673217 | G30: 52.912198 | H30: 2023 | I30: 2.4606473 | J30: 2.5 | K30: 1.0159928 | M30: Site Protection | P30: SiteProtection
A31: 30 | B31: 0 | C31: 6.1844536 | D31: 61844.536 | E31: 1047.6782 | F31: 5.4623248 | G31: 52.913554 | H31: 2023 | I31: 6.1844536 | J31: 0.5 | K31: 0.080847886 | M31: AES | N31: 37.461833 | O31: 2 | P31: Mosaics
A32: 31 | B32: 0.357 | C32: 3.7362622 | D32: 37362.622 | E32: 822.62681 | F32: 5.4738702 | G32: 52.933485 | H32: 2023 | I32: 3.7362622 | J32: 0 | K32: 0 | L32: Intermediate | M32: Site Protection | P32: SiteProtection
A33: 32 | B33: 0 | C33: 4.4861108 | D33: 44861.108 | E33: 879.04419 | F33: 5.4716038 | G33: 52.940463 | H33: 2023 | I33: 4.4861108 | J33: 0 | K33: 0 | L33: Diversified | M33: AES | N33: 146.95045 | O33: 2 | P33: NestProtection
A34: 33 | B34: 0.62 | C34: 3.7607998 | D34: 37607.998 | E34: 782.62488 | F34: 5.4720748 | G34: 52.935476 | H34: 2023 | I34: 3.7607998 | J34: 7 | K34: 1.8613062 | M34: AES | N34: 1305.1528 | O34: 3 | P34: HerbRich
A35: 34 | B35: 0.505 | C35: 3.463803 | D35: 34638.03 | E35: 817.49564 | F35: 5.442076 | G35: 52.925645 | H35: 2023 | I35: 3.463803 | J35: 0.5 | K35: 0.14435001 | M35: Site Protection | P35: SiteProtection
L36: Intensive
L37: Diversified
L38: Diversified
L39: Diversified
L40: Diversified
...

Sheet Fungi diversity
A1: Plot | B1: Sample | C1: Richness | D1: Shannon | E1: Simpson | F1: Pielou | G1: Richness_SRS | H1: s | I1: Simpson_SRS | J1: Pielou_SRS
A2: 1.1 | B2: F.BP.1 | C2: 2663 | D2: 4.52 | E2: 0.939 | F2: 0.573 | G2: 29 | H2: 2.57 | I2: 0.884 | J2: 0.764
A3: 1.2 | B3: F.BP.2 | C3: 2589 | D3: 4.49 | E3: 0.956 | F3: 0.572 | G3: 27 | H3: 2.28 | I3: 0.822 | J3: 0.691
A4: 1.3 | B4: F.BP.3 | C4: 2664 | D4: 4.48 | E4: 0.943 | F4: 0.568 | G4: 28 | H4: 1.97 | I4: 0.679 | J4: 0.592
A5: 2.1 | B5: F.BP.4 | C5: 1782 | D5: 4.56 | E5: 0.969 | F5: 0.609 | G5: 29 | H5: 2.83 | I5: 0.929 | J5: 0.84
A6: 2.2 | B6: F.BP.5 | C6: 1843 | D6: 4.42 | E6: 0.958 | F6: 0.587 | G6: 29 | H6: 2.7 | I6: 0.911 | J6: 0.801
A7: 2.3 | B7: F.BP.6 | C7: 1867 | D7: 4.6 | E7: 0.968 | F7: 0.61 | G7: 29 | H7: 2.62 | I7: 0.901 | J7: 0.777
A8: 3.1 | B8: F.BP.7 | C8: 2164 | D8: 4.45 | E8: 0.945 | F8: 0.579 | G8: 29 | H8: 2.58 | I8: 0.893 | J8: 0.767
A9: 3.2 | B9: F.BP.8 | C9: 2530 | D9: 4.37 | E9: 0.93 | F9: 0.557 | G9: 29 | H9: 2.81 | I9: 0.924 | J9: 0.836
A10: 3.3 | B10: F.BP.9 | C10: 2487 | D10: 4.5 | E10: 0.955 | F10: 0.575 | G10: 29 | H10: 2.03 | I10: 0.73 | J10: 0.603
A11: 4.1 | B11: F.BP.10 | C11: 2020 | D11: 4.01 | E11: 0.923 | F11: 0.527 | G11: 28 | H11: 2.9 | I11: 0.935 | J11: 0.871
A12: 4.2 | B12: F.BP.11 | C12: 2052 | D12: 3.64 | E12: 0.903 | F12: 0.478 | G12: 29 | H12: 2.67 | I12: 0.918 | J12: 0.794
A13: 4.3 | B13: ns | C13: ns | D13: ns | E13: ns | F13: ns | G13: ns | H13: ns | I13: ns | J13: ns
A14: 5.1 | B14: F.BP.12 | C14: 2318 | D14: 3.88 | E14: 0.906 | F14: 0.501 | G14: 28 | H14: 2.64 | I14: 0.901 | J14: 0.793
A15: 5.2 | B15: F.BP.13 | C15: 2305 | D15: 4.12 | E15: 0.943 | F15: 0.532 | G15: 28 | H15: 2.33 | I15: 0.824 | J15: 0.698
A16: 5.3 | B16: F.BP.14 | C16: 2224 | D16: 3.83 | E16: 0.931 | F16: 0.497 | G16: 28 | H16: 2.42 | I16: 0.865 | J16: 0.726
A17: 6.1 | B17: F.BP.15 | C17: 1976 | D17: 2.94 | E17: 0.775 | F17: 0.388 | G17: 27 | H17: 2.53 | I17: 0.906 | J17: 0.767
A18: 6.2 | B18: F.BP.16 | C18: 1652 | D18: 2.19 | E18: 0.589 | F18: 0.295 | G18: 27 | H18: 2.42 | I18: 0.88 | J18: 0.735
A19: 6.3 | B19: F.BP.17 | C19: 1684 | D19: 2.51 | E19: 0.662 | F19: 0.338 | G19: 28 | H19: 2.42 | I19: 0.887 | J19: 0.728
A20: 7.1 | B20: F.BP.18 | C20: 2162 | D20: 4.83 | E20: 0.978 | F20: 0.629 | G20: 30 | H20: 2.47 | I20: 0.88 | J20: 0.726
A21: 7.2 | B21: F.BP.19 | C21: 2058 | D21: 4.78 | E21: 0.971 | F21: 0.627 | G21: 29 | H21: 2.3 | I21: 0.859 | J21: 0.684
A22: 7.3 | B22: F.BP.20 | C22: 2190 | D22: 4.9 | E22: 0.978 | F22: 0.637 | G22: 30 | H22: 2.24 | I22: 0.81 | J22: 0.658
A23: 8.1 | B23: F.BP.21 | C23: 2433 | D23: 4.85 | E23: 0.977 | F23: 0.622 | G23: 28 | H23: 2.36 | I23: 0.852 | J23: 0.709
A24: 8.2 | B24: F.BP.22 | C24: 2408 | D24: 4.75 | E24: 0.962 | F24: 0.61 | G24: 28 | H24: 2.04 | I24: 0.768 | J24: 0.612
A25: 8.3 | B25: F.BP.23 | C25: 2542 | D25: 4.67 | E25: 0.966 | F25: 0.596 | G25: 27 | H25: 2.1 | I25: 0.815 | J25: 0.636
... A90: 30.2 | B90: F.BP.88 | C90: 2183 | D90: 3.9 | E90: 0.928 | F90: 0.507 | G90: 28 | H90: 2.41 | I90: 0.821 | J90: 0.723
A91: 30.3 | B91: ns | C91: ns | D91: ns | E91: ns | F91: ns | G91: ns | H91: ns | I91: ns | J91: ns
A92: 31.1 | B92: F.BP.90 | C92: 2887 | D92: 5.35 | E92: 0.988 | F92: 0.671 | G92: 28 | H92: 2.15 | I92: 0.802 | J92: 0.646
A93: 31.2 | B93: F.BP.91 | C93: 3048 | D93: 5.26 | E93: 0.986 | F93: 0.656 | G93: 28 | H93: 2.39 | I93: 0.855 | J93: 0.716
A94: 31.3 | B94: F.BP.92 | C94: 2886 | D94: 4.34 | E94: 0.921 | F94: 0.544 | G94: 28 | H94: 1.26 | I94: 0.491 | J94: 0.378
A95: 32.1 | B95: F.BP.93 | C95: 2415 | D95: 4.38 | E95: 0.958 | F95: 0.563 | G95: 28 | H95: 2.56 | I95: 0.878 | J95: 0.769
A96: 32.2 | B96: F.BP.94 | C96: 2348 | D96: 4.23 | E96: 0.954 | F96: 0.545 | G96: 27 | H96: 2.51 | I96: 0.87 | J96: 0.761
A97: 32.3 | B97: F.BP.95 | C97: 2296 | D97: 4.1 | E97: 0.951 | F97: 0.53 | G97: 28 | H97: 2.19 | I97: 0.793 | J97: 0.658
A98: 33.1 | B98: F.BP.96 | C98: 2908 | D98: 5.06 | E98: 0.981 | F98: 0.634 | G98: 27 | H98: 2.8 | I98: 0.916 | J98: 0.849
A99: 33.2 | B99: F.BP.97 | C99: 2875 | D99: 4.95 | E99: 0.978 | F99: 0.621 | G99: 28 | H99: 2.34 | I99: 0.837 | J99: 0.703
A100: 33.3 | B100: F.BP.98 | C100: 2593 | D100: 4.4 | E100: 0.963 | F100: 0.56 | G100: 28 | H100: 2.77 | I100: 0.92 | J100: 0.831
A101: 34.1 | B101: F.BP.99 | C101: 2718 | D101: 4.11 | E101: 0.887 | F101: 0.52 | G101: 28 | H101: 2.59 | I101: 0.892 | J101: 0.777
A102: 34.2 | B102: F.BP.100 | C102: 2756 | D102: 4.72 | E102: 0.946 | F102: 0.596 | G102: 28 | H102: 2.57 | I102: 0.896 | J102: 0.772
A103: 34.3 | B103: F.BP.101 | C103: 2927 | D103: 4.85 | E103: 0.947 | F103: 0.607 | G103: 28 | H103: 2.64 | I103: 0.904 | J103: 0.791

Sheet SOM
A1: Field Number | B1: Replicate | C1: Burning date | D1: Capsule | E1: Capsule_Tare | F1: Soil_Net_60 (g) | G1: Soil_Gross_105 (g) | H1: Soil_Net_105 (g) | I1: Ashes_Gross (g) | J1: Ashes_Net (g) | K1: SOM (g/kg soil) | L1: SOM_Average (g/kg soil) | M1: Ashes (%)
A2: 1 | B2: 1 | D2: 746 | E2: 22.42 | F2: 20.103 | G2: 42.272 | H2: =G2-E2 -> 19.852 | I2: 39.618 | J2: =I2-E2 -> 17.198 | K2: =((H2-J2)/H2)*1000 -> 133.6893 | L2: =AVERAGE(K2:K4) -> 133.02714 | M2: =100*J2/H2 -> 86.63107
A3: 1 | B3: 2 | D3: 703 | E3: 22.579 | F3: 19.975 | G3: 42.302 | H3: =G3-E3 -> 19.723 | I3: 39.541 | J3: =I3-E3 -> 16.962 | K3: =((H3-J3)/H3)*1000 -> 139.98885 | M3: =100*J3/H3 -> 86.001115
A4: 1 | B4: 3 | D4: 555 | E4: 18.7 | F4: 19.485 | G4: 37.918 | H4: =G4-E4 -> 19.218 | I4: 35.508 | J4: =I4-E4 -> 16.808 | K4: =((H4-J4)/H4)*1000 -> 125.40327 | M4: =100*J4/H4 -> 87.459673
A5: 2 | B5: 1 | D5: 365 | E5: 19.213 | F5: 19.792 | G5: 38.745 | H5: =G5-E5 -> 19.532 | I5: 36.22 | J5: =I5-E5 -> 17.007 | K5: =((H5-J5)/H5)*1000 -> 129.27504 | L5: =AVERAGE(K5:K7) -> 134.86052 | M5: =100*J5/H5 -> 87.072496
A6: 2 | B6: 2 | D6: 576 | E6: 17.972 | F6: 20.126 | G6: 37.844 | H6: =G6-E6 -> 19.872 | I6: 35.15 | J6: =I6-E6 -> 17.178 | K6: =((H6-J6)/H6)*1000 -> 135.56763 | M6: =100*J6/H6 -> 86.443237
A7: 2 | B7: 3 | D7: 476 | E7: 20.305 | F7: 19.639 | G7: 39.684 | H7: =G7-E7 -> 19.379 | I7: 36.976 | J7: =I7-E7 -> 16.671 | K7: =((H7-J7)/H7)*1000 -> 139.73889 | M7: =100*J7/H7 -> 86.026111
A8: 3 | B8: 1 | D8: 398 | E8: 19.166 | F8: 19.736 | G8: 38.639 | H8: =G8-E8 -> 19.473 | I8: 35.727 | J8: =I8-E8 -> 16.561 | K8: =((H8-J8)/H8)*1000 -> 149.54039 | L8: =AVERAGE(K9:K10) -> 145.75197 | M8: =100*J8/H8 -> 85.045961
A9: 3 | B9: 2 | D9: 377 | E9: 18.687 | F9: 19.53 | G9: 37.964 | H9: =G9-E9 -> 19.277 | I9: 35.143 | J9: =I9-E9 -> 16.456 | K9: =((H9-J9)/H9)*1000 -> 146.3402 | M9: =100*J9/H9 -> 85.36598
A10: 3 | B10: 3 | D10: 765 | E10: 18.1 | F10: 20.024 | G10: 37.857 | H10: =G10-E10 -> 19.757 | I10: 34.989 | J10: =I10-E10 -> 16.889 | K10: =((H10-J10)/H10)*1000 -> 145.16374 | M10: =100*J10/H10 -> 85.483626
A11: 4 | B11: 1 | D11: 785 | E11: 22.595 | F11: 20.443 | G11: 42.876 | H11: =G11-E11 -> 20.281 | I11: 41.222 | J11: =I11-E11 -> 18.627 | K11: =((H11-J11)/H11)*1000 -> 81.554164 | L11: =AVERAGE(K11:K13) -> 75.562302 | M11: =100*J11/H11 -> 91.844584
A12: 4 | B12: 2 | D12: 386 | E12: 18.972 | F12: 19.965 | G12: 38.795 | H12: =G12-E12 -> 19.823 | I12: 37.352 | J12: =I12-E12 -> 18.38 | K12: =((H12-J12)/H12)*1000 -> 72.794229 | M12: =100*J12/H12 -> 92.720577
A13: 4 | B13: 3 | D13: 767 | E13: 22.664 | F13: 20.151 | G13: 42.681 | H13: =G13-E13 -> 20.017 | I13: 41.233 | J13: =I13-E13 -> 18.569 | K13: =((H13-J13)/H13)*1000 -> 72.338512 | M13: =100*J13/H13 -> 92.766149
A14: 5 | B14: 1 | D14: 532 | E14: 19.291 | F14: 20.632 | G14: 39.705 | H14: =G14-E14 -> 20.414 | I14: 37.703 | J14: =I14-E14 -> 18.412 | K14: =((H14-J14)/H14)*1000 -> 98.069952 | L14: =AVERAGE(K14:K16) -> 95.49698 | M14: =100*J14/H14 -> 90.193005
A15: 5 | B15: 2 | D15: 367 | E15: 18.644 | F15: 20.216 | G15: 38.659 | H15: =G15-E15 -> 20.015 | I15: 36.774 | J15: =I15-E15 -> 18.13 | K15: =((H15-J15)/H15)*1000 -> 94.179365 | M15: =100*J15/H15 -> 90.582063
A16: 5 | B16: 3 | D16: 580 | E16: 18.734 | F16: 20.203 | G16: 38.757 | H16: =G16-E16 -> 20.023 | I16: 36.87 | J16: =I16-E16 -> 18.136 | K16: =((H16-J16)/H16)*1000 -> 94.241622 | M16: =100*J16/H16 -> 90.575838
A17: 6 | B17: 1 | D17: 392 | E17: 19.893 | F17: 20.041 | G17: 39.775 | H17: =G17-E17 -> 19.882 | I17: 37.975 | J17: =I17-E17 -> 18.082 | K17: =((H17-J17)/H17)*1000 -> 90.534151 | L17: =AVERAGE(K17:K19) -> 88.485865 | M17: =100*J17/H17 -> 90.946585
A18: 6 | B18: 2 | D18: 550 | E18: 19.538 | F18: 20.194 | G18: 39.532 | H18: =G18-E18 -> 19.994 | I18: 37.647 | J18: =I18-E18 -> 18.109 | K18: =((H18-J18)/H18)*1000 -> 94.278283 | M18: =100*J18/H18 -> 90.572172
A19: 6 | B19: 3 | D19: 786 | E19: 22.69 | F19: 20.34 | G19: 42.84 | H19: =G19-E19 -> 20.15 | I19: 41.215 | J19: =I19-E19 -> 18.525 | K19: =((H19-J19)/H19)*1000 -> 80.645161 | M19: =100*J19/H19 -> 91.935484
A20: 7 | B20: 1 | D20: 378 | E20: 19.552 | F20: 20.358 | G20: 39.716 | H20: =G20-E20 -> 20.164 | I20: 37.996 | J20: =I20-E20 -> 18.444 | K20: =((H20-J20)/H20)*1000 -> 85.300536 | L20: =AVERAGE(K20:K22) -> 81.466575 | M20: =100*J20/H20 -> 91.469946
A21: 7 | B21: 2 | D21: 523 | E21: 18.336 | F21: 20.19 | G21: 38.345 | H21: =G21-E21 -> 20.009 | I21: 36.694 | J21: =I21-E21 -> 18.358 | K21: =((H21-J21)/H21)*1000 -> 82.512869 | M21: =100*J21/H21 -> 91.748713
A22: 7 | B22: 3 | D22: 445 | E22: 18.901 | F22: 19.584 | G22: 38.317 | H22: =G22-E22 -> 19.416 | I22: 36.83 | J22: =I22-E22 -> 17.929 | K22: =((H22-J22)/H22)*1000 -> 76.586321 | M22: =100*J22/H22 -> 92.341368
A23: 8 | B23: 1 | D23: 371 | E23: 18.692 | F23: 18.017 | G23: 36.553 | H23: =G23-E23 -> 17.861 | I23: 35.045 | J23: =I23-E23 -> 16.353 | K23: =((H23-J23)/H23)*1000 -> 84.429763 | L23: =AVERAGE(K23:K25) -> 86.356789 | M23: =100*J23/H23 -> 91.557024
A24: 8 | B24: 2 | D24: 444 | E24: 18.88 | F24: 20.798 | G24: 39.516 | H24: =G24-E24 -> 20.636 | I24: 37.747 | J24: =I24-E24 -> 18.867 | K24: =((H24-J24)/H24)*1000 -> 85.723978 | M24: =100*J24/H24 -> 91.427602
A25: 8 | B25: 3 | D25: 552 | E25: 19.602 | F25: 20.195 | G25: 39.632 | H25: =G25-E25 -> 20.03 | I25: 37.851 | J25: =I25-E25 -> 18.249 | K25: =((H25-J25)/H25)*1000 -> 88.916625 | M25: =100*J25/H25 -> 91.108337
A26: 9 | B26: 1 | D26: 401 | E26: 19.501 | F26: 20.215 | G26: 39.54 | H26: =G26-E26 -> 20.039 | I26: 37.805 | J26: =I26-E26 -> 18.304 | K26: =((H26-J26)/H26)*1000 -> 86.581167 | L26: =AVERAGE(K26:K28) -> 108.28354 | M26: =100*J26/H26 -> 91.341883
A27: 9 | B27: 2 | D27: 562 | E27: 18.98 | F27: 20.026 | G27: 38.819 | H27: =G27-E27 -> 19.839 | I27: 36.739 | J27: =I27-E27 -> 17.759 | K27: =((H27-J27)/H27)*1000 -> 104.84399 | M27: =100*J27/H27 -> 89.515601
A28: 9 | B28: 3 | D28: 561 | E28: 18.935 | F28: 19.759 | G28: 38.474 | H28: =G28-E28 -> 19.539 | I28: 35.867 | J28: =I28-E28 -> 16.932 | K28: =((H28-J28)/H28)*1000 -> 133.42546 | M28: =100*J28/H28 -> 86.657454
A29: 10 | B29: 1 | D29: 449 | E29: 18.29 | F29: 20.133 | G29: 38.119 | H29: =G29-E29 -> 19.829 | I29: 35.096 | J29: =I29-E29 -> 16.806 | K29: =((H29-J29)/H29)*1000 -> 152.45348 | L29: =AVERAGE(K29:K31) -> 149.71016 | M29: =100*J29/H29 -> 84.754652
A30: 10 | B30: 2 | D30: 732 | E30: 18.72 | F30: 20.468 | G30: 38.872 | H30: =G30-E30 -> 20.152 | I30: 35.819 | J30: =I30-E30 -> 17.099 | K30: =((H30-J30)/H30)*1000 -> 151.49861 | M30: =100*J30/H30 -> 84.850139
A31: 10 | B31: 3 | D31: 724 | E31: 22.073 | F31: 20.115 | G31: 41.89 | H31: =G31-E31 -> 19.817 | I31: 39.013 | J31: =I31-E31 -> 16.94 | K31: =((H31-J31)/H31)*1000 -> 145.17838 | M31: =100*J31/H31 -> 85.482162
A32: 11 | B32: 1 | D32: 716 | E32: 22.943 | F32: 20.13 | G32: 42.865 | H32: =G32-E32 -> 19.922 | I32: 41.24 | J32: =I32-E32 -> 18.297 | K32: =((H32-J32)/H32)*1000 -> 81.568116 | L32: =AVERAGE(K32:K34) -> 103.93965 | M32: =100*J32/H32 -> 91.843188
A33: 11 | B33: 2 | D33: 717 | E33: 18.468 | F33: 20.338 | G33: 38.586 | H33: =G33-E33 -> 20.118 | I33: 35.531 | J33: =I33-E33 -> 17.063 | K33: =((H33-J33)/H33)*1000 -> 151.85406 | M33: =100*J33/H33 -> 84.814594
A34: 11 | B34: 3 | D34: 569 | E34: 19.392 | F34: 20.053 | G34: 39.227 | H34: =G34-E34 -> 19.835 | I34: 37.672 | J34: =I34-E34 -> 18.28 | K34: =((H34-J34)/H34)*1000 -> 78.396773 | M34: =100*J34/H34 -> 92.160323
A35: 12 | B35: 1 | D35: 768 | E35: 23.543 | F35: 20.273 | G35: 43.656 | H35: =G35-E35 -> 20.113 | I35: 41.955 | J35: =I35-E35 -> 18.412 | K35: =((H35-J35)/H35)*1000 -> 84.572167 | L35: =AVERAGE(K35:K37) -> 82.965685 | M35: =100*J35/H35 -> 91.542783
A36: 12 | B36: 2 | D36: 517 | E36: 18.431 | F36: 20.45 | G36: 38.72 | H36: =G36-E36 -> 20.289 | I36: 37.071 | J36: =I36-E36 -> 18.64 | K36: =((H36-J36)/H36)*1000 -> 81.275568 | M36: =100*J36/H36 -> 91.872443
A37: 12 | B37: 3 | D37: 707 | E37: 22.981 | F37: 20.174 | G37: 42.933 | H37: =G37-E37 -> 19.952 | I37: 41.276 | J37: =I37-E37 -> 18.295 | K37: =((H37-J37)/H37)*1000 -> 83.049318 | M37: =100*J37/H37 -> 91.695068
A38: 13 | B38: 1 | D38: 558 | E38: 19.595 | F38: 20.203 | G38: 39.495 | H38: =G38-E38 -> 19.9 | I38: 37.262 | J38: =I38-E38 -> 17.667 | K38: =((H38-J38)/H38)*1000 -> 112.21106 | L38: =AVERAGE(K38:K40) -> 117.22089 | M38: =100*J38/H38 -> 88.778894
A39: 13 | B39: 2 | D39: 568 | E39: 18.809 | F39: 20.06 | G39: 38.599 | H39: =G39-E39 -> 19.79 | I39: 36.135 | J39: =I39-E39 -> 17.326 | K39: =((H39-J39)/H39)*1000 -> 124.50733 | M39: =100*J39/H39 -> 87.549267
A40: 13 | B40: 3 | D40: 501 | E40: 19.03 | F40: 20.018 | G40: 38.77 | H40: =G40-E40 -> 19.74 | I40: 36.501 | J40: =I40-E40 -> 17.471 | K40: =((H40-J40)/H40)*1000 -> 114.94428 | M40: =100*J40/H40 -> 88.505572
...

Sheet POM
A1: Field Number | B1: Replicate | C1: Burning date | D1: Jar Nº | E1: Soil_Net (g) | F1: Soil_Net_105_corrected (g) | G1: Capsule Nº | H1: Capsule Tare | I1: Dried_Coarse_Fraction_Gross (g) | J1: Dried_Coarse_Fraction_NET (g) | K1: Ashes_Gross (g) | L1: Ashes_Net (g) | M1: POM (g/kg soil) | N1: POM_Average (g/kg soil) | O1: Total_Ashes (%) | P1: Sand (%) | Q1: Clay+silt (%) | R1: Clay+Silt_Average (%)
A2: 1 | B2: 1 | C2: 30.07.24 | D2: 1.1 | E2: 20.112 | F2: 19.860888 | G2: 218 | H2: 19.146 | I2: 24.226 | J2: 5.08 | K2: 23.535 | L2: 4.389 | M2: 34.792 | N2: 43.445945 | O2: 86.63107 | P2: 25.508989 | Q2: 74.491011 | R2: 72.270932
A3: 1 | B3: 2 | C3: 30.07.24 | D3: 1.2 | E3: 20.022 | F3: 19.769407 | G3: 545 | H3: 19.619 | I3: 25.38 | J3: 5.761 | K3: 24.507 | L3: 4.888 | M3: 44.159139 | O3: 86.001115 | P3: 28.74971 | Q3: 71.25029
A4: 1 | B4: 3 | C4: 30.07.24 | D4: 1.3 | E4: 20.145 | F4: 19.868956 | G4: 450 | H4: 20.339 | I4: 26.387 | J4: 6.048 | K4: 25.366 | L4: 5.027 | M4: 51.386696 | O4: 87.459673 | P4: 28.928505 | Q4: 71.071495
A5: 2 | B5: 1 | C5: 30.07.24 | D5: 2.1 | E5: 20.462 | F5: 20.193198 | G5: 582 | H5: 19.078 | I5: 22.806 | J5: 3.728 | K5: 22.11 | L5: 3.032 | M5: 34.467051 | N5: 37.233763 | O5: 87.072496 | P5: 17.244201 | Q5: 82.755799 | R5: 82.07859
A6: 2 | B6: 2 | C6: 30.07.24 | D6: 2.2 | E6: 20.052 | F6: 19.798934 | G6: 508 | H6: 20.118 | I6: 23.88 | J6: 3.762 | K6: 23.135 | L6: 3.017 | M6: 37.628289 | O6: 86.443237 | P6: 17.627977 | Q6: 82.372023
A7: 2 | B7: 3 | C7: 30.07.24 | D7: 2.3 | E7: 20.035 | F7: 19.769757 | G7: 507 | H7: 18.84 | I7: 22.836 | J7: 3.996 | K7: 22.053 | L7: 3.213 | M7: 39.605949 | O7: 86.026111 | P7: 18.89205 | Q7: 81.10795
A8: 3 | B8: 1 | C8: 30.07.24 | D8: 3.1 | E8: 20.11 | F8: 19.842016 | G8: 514 | H8: 19.243 | I8: 26.307 | J8: 7.064 | K8: 25.505 | L8: 6.262 | M8: 40.41928 | N8: 41.267684 | O8: 85.045961 | P8: 37.108515 | Q8: 62.891485 | R8: 62.432332
A9: 3 | B9: 2 | C9: 30.07.24 | D9: 3.2 | E9: 20.108 | F9: 19.847512 | G9: 438 | H9: 19.966 | I9: 26.891 | J9: 6.925 | K9: 26.09 | L9: 6.124 | M9: 40.357703 | O9: 85.36598 | P9: 36.144671 | Q9: 63.855329
A10: 3 | B10: 3 | C10: 30.07.24 | D10: 3.3 | E10: 20.046 | F10: 19.778707 | G10: 593 | H10: 19.829 | I10: 27.35 | J10: 7.521 | K10: 26.499 | L10: 6.67 | M10: 43.026069 | O10: 85.483626 | P10: 39.449818 | Q10: 60.550182
A11: 4 | B11: 1 | C11: 30.07.24 | D11: 4.1 | E11: 20.06 | F11: 19.901035 | G11: 405 | H11: 19.563 | I11: 28.419 | J11: 8.856 | K11: 27.824 | L11: 8.261 | M11: 29.897942 | N11: 28.266326 | O11: 91.844584 | P11: 45.196355 | Q11: 54.803645 | R11: 53.294394
A12: 4 | B12: 2 | C12: 30.07.24 | D12: 4.2 | E12: 20.005 | F12: 19.862716 | G12: 505 | H12: 19.677 | I12: 29.028 | J12: 9.351 | K12: 28.472 | L12: 8.795 | M12: 27.992144 | O12: 92.720577 | P12: 47.755247 | Q12: 52.244753
A13: 4 | B13: 3 | C13: 30.07.24 | D13: 4.3 | E13: 20.015 | F13: 19.881904 | G13: 497 | H13: 20.02 | I13: 29.254 | J13: 9.234 | K13: 28.719 | L13: 8.699 | M13: 26.908891 | O13: 92.766149 | P13: 47.165216 | Q13: 52.834784
A14: 5 | B14: 1 | C14: 30.07.24 | D14: 5.1 | E14: 20.065 | F14: 19.852991 | G14: 346 | H14: 18.839 | I14: 27.383 | J14: 8.544 | K14: 26.79 | L14: 7.951 | M14: 29.869555 | N14: 30.112077 | O14: 90.193005 | P14: 44.404088 | Q14: 55.595912 | R14: 50.823765
A15: 5 | B15: 2 | C15: 30.07.24 | D15: 5.2 | E15: 20.128 | F15: 19.927875 | G15: 519 | H15: 19.016 | I15: 28.381 | J15: 9.365 | K15: 27.805 | L15: 8.789 | M15: 28.904236 | O15: 90.582063 | P15: 48.689607 | Q15: 51.310393
A16: 5 | B16: 3 | C16: 30.07.24 | D16: 5.3 | E16: 20.012 | F16: 19.833702 | G16: 482 | H16: 19.934 | I16: 30.339 | J16: 10.405 | K16: 29.713 | L16: 9.779 | M16: 31.562439 | O16: 90.575838 | P16: 54.43501 | Q16: 45.56499
A17: 6 | B17: 1 | C17: 30.07.24 | D17: 6.1 | E17: 20.25 | F17: 20.089342 | G17: 169 | H17: 19.739 | I17: 31.966 | J17: 12.227 | K17: 31.15 | L17: 11.411 | M17: 40.618553 | N17: 47.483048 | O17: 90.946585 | P17: 62.455631 | Q17: 37.544369 | R17: 31.482129
A18: 6 | B18: 2 | C18: 30.07.24 | D18: 6.2 | E18: 20.221 | F18: 20.020733 | G18: 951 | H18: 19.307 | I18: 36.918 | J18: 17.611 | K18: 35.839 | L18: 16.532 | M18: 53.894132 | O18: 90.572172 | P18: 91.169726 | Q18: 8.8302738
A19: 6 | B19: 3 | C19: 30.07.24 | D19: 6.3 | E19: 20.089 | F19: 19.901345 | G19: 536 | H19: 22.641 | I19: 33.096 | J19: 10.455 | K19: 32.142 | L19: 9.501 | M19: 47.936459 | O19: 91.935484 | P19: 51.928255 | Q19: 48.071745
A20: 7 | B20: 1 | C20: 6.08.24 | D20: 7.1 | E20: 20.017 | F20: 19.82625 | G20: 435 | H20: 19.404 | I20: 33.536 | J20: 14.132 | K20: 32.618 | L20: 13.214 | M20: 46.302252 | N20: 46.171971 | O20: 91.469946 | P20: 72.864386 | Q20: 27.135614 | R20: 28.112173
A21: 7 | B21: 2 | C21: 6.08.24 | D21: 7.2 | E21: 20 | F21: 19.820703 | G21: 738 | H21: 22.504 | I21: 37.151 | J21: 14.647 | K21: 36.142 | L21: 13.638 | M21: 50.906367 | O21: 91.748713 | P21: 74.994885 | Q21: 25.005115
A22: 7 | B22: 3 | C22: 6.08.24 | D22: 7.3 | E22: 20.316 | F22: 20.141721 | G22: 553 | H22: 19.107 | I22: 32.55 | J22: 13.443 | K22: 31.718 | L22: 12.611 | M22: 41.307295 | O22: 92.341368 | P22: 67.804209 | Q22: 32.195791
A23: 8 | B23: 1 | C23: 6.08.24 | D23: 8.1 | E23: 20.343 | F23: 20.16686 | G23: 437 | H23: 19.29 | I23: 42.138 | J23: 22.848 | K23: 40.685 | L23: 21.395 | M23: 72.048895 | N23: 61.034567 | O23: 91.557024 | P23: 115.87302 | Q23: - | R23: =AVERAGE(Q24:Q25) -> 14.849437
A24: 8 | B24: 2 | C24: 6.08.24 | D24: 8.2 | E24: 20.459 | F24: 20.299641 | G24: 719 | H24: 22.68 | I24: 39.523 | J24: 16.843 | K24: 38.48 | L24: 15.8 | M24: 51.38022 | O24: 91.427602 | P24: 85.13172 | Q24: 14.86828
A25: 8 | B25: 3 | C25: 6.08.24 | D25: 8.3 | E25: 20.714 | F25: 20.54476 | G25: 396 | H25: 19.162 | I25: 36.33 | J25: 17.168 | K25: 35.104 | L25: 15.942 | M25: 59.674585 | O25: 91.108337 | P25: 85.169406 | Q25: 14.830594
A26: 9 | B26: 1 | C26: 6.08.24 | D26: 9.1 | E26: 20.022 | F26: 19.84768 | G26: 408 | H26: 18.462 | I26: 34.18 | J26: 15.718 | K26: 33.153 | L26: 14.691 | M26: 51.744082 | N26: 69.176484 | O26: 91.341883 | P26: 81.034814 | Q26: 18.965186 | R26: 17.377431
A27: 9 | B27: 2 | C27: 6.08.24 | D27: 9.2 | E27: 20.001 | F27: 19.814233 | G27: 395 | H27: 20.365 | I27: 36.278 | J27: 15.913 | K27: 34.951 | L27: 14.586 | M27: 66.972058 | O27: 89.515601 | P27: 82.235664 | Q27: 17.764336
A28: 9 | B28: 3 | C28: 6.08.24 | D28: 9.3 | E28: 20.188 | F28: 19.963223 | G28: 794 | H28: 18.443 | I28: 34.851 | J28: 16.408 | K28: 33.078 | L28: 14.635 | M28: 88.813312 | O28: 86.657454 | P28: 84.597228 | Q28: 15.402772
A29: 10 | B29: 1 | C29: 6.08.24 | D29: 10.1 | E29: 20.05 | F29: 19.747253 | G29: 699 | H29: 23.061 | I29: 31.667 | J29: 8.606 | K29: 30.426 | L29: 7.365 | M29: 62.844183 | N29: 55.396353 | O29: 84.754652 | P29: 44.005049 | Q29: 55.994951 | R29: 64.226083
A30: 10 | B30: 2 | C30: 6.08.24 | D30: 10.2 | E30: 20.085 | F30: 19.774913 | G30: 370 | H30: 19.655 | I30: 26.646 | J30: 6.991 | K30: 25.549 | L30: 5.894 | M30: 55.474327 | O30: 84.850139 | P30: 35.127156 | Q30: 64.872844
A31: 10 | B31: 3 | C31: 6.08.24 | D31: 10.3 | E31: 20.08 | F31: 19.782519 | G31: 418 | H31: 18.76 | I31: 24.474 | J31: 5.714 | K31: 23.527 | L31: 4.767 | M31: 47.870548 | O31: 85.482162 | P31: 28.189546 | Q31: 71.810454
A32: 11 | B32: 1 | C32: 6.08.24 | D32: 11.1 | E32: 20.048 | F32: 19.840847 | G32: 777 | H32: 18.785 | I32: 24.715 | J32: 5.93 | K32: 24.29 | L32: 5.505 | M32: 21.420456 | N32: 20.805897 | O32: 91.843188 | P32: 30.20996 | Q32: 69.79004 | R32: 68.165977
A33: 11 | B33: 2 | C33: 6.08.24 | D33: 11.2 | E33: 20.058 | F33: 19.841029 | G33: 714 | H33: 22.923 | I33: 28.808 | J33: 5.885 | K33: 28.392 | L33: 5.469 | M33: 20.966655 | O33: 84.814594 | P33: 32.499236 | Q33: 67.500764
A34: 11 | B34: 3 | C34: 6.08.24 | D34: 11.3 | E34: 20.088 | F34: 19.86962 | G34: 440 | H34: 19.101 | I34: 25.504 | J34: 6.403 | K34: 25.106 | L34: 6.005 | M34: 20.03058 | O34: 92.160323 | P34: 32.792874 | Q34: 67.207126
A35: 12 | B35: 1 | C35: 6.08.24 | D35: 12.1 | E35: 20.07 | F35: 19.911602 | G35: 535 | H35: 19.486 | I35: 30.234 | J35: 10.748 | K35: 29.449 | L35: 9.963 | M35: 39.424251 | N35: 37.328244 | O35: 91.542783 | P35: 54.658765 | Q35: 45.341235 | R35: 47.008872
A36: 12 | B36: 2 | C36: 6.08.24 | D36: 12.2 | E36: 20.088 | F36: 19.92985 | G36: 799 | H36: 22.232 | I36: 32.462 | J36: 10.23 | K36: 31.767 | L36: 9.535 | M36: 34.872315 | O36: 91.872443 | P36: 52.075255 | Q36: 47.924745
A37: 12 | B37: 3 | C37: 6.08.24 | D37: 12.3 | E37: 20.524 | F37: 20.298149 | G37: 399 | H37: 17.991 | I37: 28.479 | J37: 10.488 | K37: 27.714 | L37: 9.723 | M37: 37.688166 | O37: 91.695068 | P37: 52.239364 | Q37: 47.760636
A38: 13 | B38: 1 | C38: 13.08.24 | D38: 13.1 | E38: 20.285 | F38: 19.98077 | G38: 589 | H38: 19.625 | I38: 23.235 | J38: 3.61 | K38: 22.7 | L38: 3.075 | M38: 26.775745 | N38: 28.641395 | O38: 88.778894 | P38: 17.334973 | Q38: 82.665027 | R38: 82.560234
A39: 13 | B39: 2 | C39: 13.08.24 | D39: 13.2 | E39: 20.075 | F39: 19.804798 | G39: 512 | H39: 18.685 | I39: 22.453 | J39: 3.768 | K39: 21.826 | L39: 3.141 | M39: 31.658995 | O39: 87.549267 | P39: 18.115278 | Q39: 81.884722
A40: 13 | B40: 3 | C40: 13.08.24 | D40: 13.3 | E40: 20.105 | F40: 19.825792 | G40: 592 | H40: 19.178 | I40: 22.683 | J40: 3.505 | K40: 22.138 | L40: 2.96 | M40: 27.489444 | O40: 88.505572 | P40: 16.869047 | Q40: 83.130953
...

Sheet MAOM
A1: Field number | B1: Replicate | C1: MAOM (g/kg)
A2: =POM!A2 -> 1 | B2: =POM!B2 -> 1 | C2: 98.9
A3: =POM!A3 -> 1 | B3: =POM!B3 -> 2 | C3: 95.83
A4: =POM!A4 -> 1 | B4: =POM!B4 -> 3 | C4: 74.02
A5: =POM!A5 -> 2 | B5: =POM!B5 -> 1 | C5: 94.81
A6: =POM!A6 -> 2 | B6: =POM!B6 -> 2 | C6: 97.94
A7: =POM!A7 -> 2 | B7: =POM!B7 -> 3 | C7: 100.13
A8: =POM!A8 -> 3 | B8: =POM!B8 -> 1 | C8: 109.12
A9: =POM!A9 -> 3 | B9: =POM!B9 -> 2 | C9: 105.98
A10: =POM!A10 -> 3 | B10: =POM!B10 -> 3 | C10: 102.14
A11: =POM!A11 -> 4 | B11: =POM!B11 -> 1 | C11: 51.66
A12: =POM!A12 -> 4 | B12: =POM!B12 -> 2 | C12: 44.8
A13: =POM!A13 -> 4 | B13: =POM!B13 -> 3 | C13: 45.43
... A103: =POM!A103 -> 34 | B103: =POM!B103 -> 3 | C103: 40.92
